{
 "cells": [
  {
   "cell_type": "code",
   "execution_count": 7,
   "metadata": {},
   "outputs": [],
   "source": [
    "import os\n",
    "import io\n",
    "import boto3\n",
    "import json\n",
    "import csv\n",
    "import sagemaker"
   ]
  },
  {
   "cell_type": "code",
   "execution_count": 3,
   "metadata": {},
   "outputs": [],
   "source": [
    "runtime= boto3.client('runtime.sagemaker')"
   ]
  },
  {
   "cell_type": "code",
   "execution_count": 6,
   "metadata": {},
   "outputs": [
    {
     "ename": "ModelError",
     "evalue": "An error occurred (ModelError) when calling the InvokeEndpoint operation: Received client error (400) from model with message \"unable to evaluate payload provided\". See https://us-east-1.console.aws.amazon.com/cloudwatch/home?region=us-east-1#logEventViewer:group=/aws/sagemaker/Endpoints/object-detection-2021-03-02-21-09-42-717 in account 468910889761 for more information.",
     "output_type": "error",
     "traceback": [
      "\u001b[0;31m---------------------------------------------------------------------------\u001b[0m",
      "\u001b[0;31mModelError\u001b[0m                                Traceback (most recent call last)",
      "\u001b[0;32m<ipython-input-6-7f553f1aeb41>\u001b[0m in \u001b[0;36m<module>\u001b[0;34m\u001b[0m\n\u001b[0;32m----> 1\u001b[0;31m \u001b[0mresponse\u001b[0m \u001b[0;34m=\u001b[0m \u001b[0mruntime\u001b[0m\u001b[0;34m.\u001b[0m\u001b[0minvoke_endpoint\u001b[0m\u001b[0;34m(\u001b[0m\u001b[0mEndpointName\u001b[0m\u001b[0;34m=\u001b[0m\u001b[0;34m'object-detection-2021-03-02-21-09-42-717'\u001b[0m\u001b[0;34m,\u001b[0m \u001b[0mBody\u001b[0m\u001b[0;34m=\u001b[0m\u001b[0;34m'file'\u001b[0m\u001b[0;34m)\u001b[0m\u001b[0;34m\u001b[0m\u001b[0;34m\u001b[0m\u001b[0m\n\u001b[0m",
      "\u001b[0;32m/opt/conda/lib/python3.7/site-packages/botocore/client.py\u001b[0m in \u001b[0;36m_api_call\u001b[0;34m(self, *args, **kwargs)\u001b[0m\n\u001b[1;32m    355\u001b[0m                     \"%s() only accepts keyword arguments.\" % py_operation_name)\n\u001b[1;32m    356\u001b[0m             \u001b[0;31m# The \"self\" in this scope is referring to the BaseClient.\u001b[0m\u001b[0;34m\u001b[0m\u001b[0;34m\u001b[0m\u001b[0;34m\u001b[0m\u001b[0m\n\u001b[0;32m--> 357\u001b[0;31m             \u001b[0;32mreturn\u001b[0m \u001b[0mself\u001b[0m\u001b[0;34m.\u001b[0m\u001b[0m_make_api_call\u001b[0m\u001b[0;34m(\u001b[0m\u001b[0moperation_name\u001b[0m\u001b[0;34m,\u001b[0m \u001b[0mkwargs\u001b[0m\u001b[0;34m)\u001b[0m\u001b[0;34m\u001b[0m\u001b[0;34m\u001b[0m\u001b[0m\n\u001b[0m\u001b[1;32m    358\u001b[0m \u001b[0;34m\u001b[0m\u001b[0m\n\u001b[1;32m    359\u001b[0m         \u001b[0m_api_call\u001b[0m\u001b[0;34m.\u001b[0m\u001b[0m__name__\u001b[0m \u001b[0;34m=\u001b[0m \u001b[0mstr\u001b[0m\u001b[0;34m(\u001b[0m\u001b[0mpy_operation_name\u001b[0m\u001b[0;34m)\u001b[0m\u001b[0;34m\u001b[0m\u001b[0;34m\u001b[0m\u001b[0m\n",
      "\u001b[0;32m/opt/conda/lib/python3.7/site-packages/botocore/client.py\u001b[0m in \u001b[0;36m_make_api_call\u001b[0;34m(self, operation_name, api_params)\u001b[0m\n\u001b[1;32m    674\u001b[0m             \u001b[0merror_code\u001b[0m \u001b[0;34m=\u001b[0m \u001b[0mparsed_response\u001b[0m\u001b[0;34m.\u001b[0m\u001b[0mget\u001b[0m\u001b[0;34m(\u001b[0m\u001b[0;34m\"Error\"\u001b[0m\u001b[0;34m,\u001b[0m \u001b[0;34m{\u001b[0m\u001b[0;34m}\u001b[0m\u001b[0;34m)\u001b[0m\u001b[0;34m.\u001b[0m\u001b[0mget\u001b[0m\u001b[0;34m(\u001b[0m\u001b[0;34m\"Code\"\u001b[0m\u001b[0;34m)\u001b[0m\u001b[0;34m\u001b[0m\u001b[0;34m\u001b[0m\u001b[0m\n\u001b[1;32m    675\u001b[0m             \u001b[0merror_class\u001b[0m \u001b[0;34m=\u001b[0m \u001b[0mself\u001b[0m\u001b[0;34m.\u001b[0m\u001b[0mexceptions\u001b[0m\u001b[0;34m.\u001b[0m\u001b[0mfrom_code\u001b[0m\u001b[0;34m(\u001b[0m\u001b[0merror_code\u001b[0m\u001b[0;34m)\u001b[0m\u001b[0;34m\u001b[0m\u001b[0;34m\u001b[0m\u001b[0m\n\u001b[0;32m--> 676\u001b[0;31m             \u001b[0;32mraise\u001b[0m \u001b[0merror_class\u001b[0m\u001b[0;34m(\u001b[0m\u001b[0mparsed_response\u001b[0m\u001b[0;34m,\u001b[0m \u001b[0moperation_name\u001b[0m\u001b[0;34m)\u001b[0m\u001b[0;34m\u001b[0m\u001b[0;34m\u001b[0m\u001b[0m\n\u001b[0m\u001b[1;32m    677\u001b[0m         \u001b[0;32melse\u001b[0m\u001b[0;34m:\u001b[0m\u001b[0;34m\u001b[0m\u001b[0;34m\u001b[0m\u001b[0m\n\u001b[1;32m    678\u001b[0m             \u001b[0;32mreturn\u001b[0m \u001b[0mparsed_response\u001b[0m\u001b[0;34m\u001b[0m\u001b[0;34m\u001b[0m\u001b[0m\n",
      "\u001b[0;31mModelError\u001b[0m: An error occurred (ModelError) when calling the InvokeEndpoint operation: Received client error (400) from model with message \"unable to evaluate payload provided\". See https://us-east-1.console.aws.amazon.com/cloudwatch/home?region=us-east-1#logEventViewer:group=/aws/sagemaker/Endpoints/object-detection-2021-03-02-21-09-42-717 in account 468910889761 for more information."
     ]
    }
   ],
   "source": []
  },
  {
   "cell_type": "code",
   "execution_count": null,
   "metadata": {},
   "outputs": [],
   "source": []
  }
 ],
 "metadata": {
  "kernelspec": {
   "display_name": "Python 3 (Data Science)",
   "language": "python",
   "name": "python3__SAGEMAKER_INTERNAL__arn:aws:sagemaker:us-east-1:081325390199:image/datascience-1.0"
  },
  "language_info": {
   "codemirror_mode": {
    "name": "ipython",
    "version": 3
   },
   "file_extension": ".py",
   "mimetype": "text/x-python",
   "name": "python",
   "nbconvert_exporter": "python",
   "pygments_lexer": "ipython3",
   "version": "3.7.6"
  }
 },
 "nbformat": 4,
 "nbformat_minor": 4
}
